Watching for file changes with StatReloader
"GET /admin/auth/user/ HTTP/1.1" 200 11072
"GET /admin/jsi18n/ HTTP/1.1" 200 3342
"GET /admin/auth/user/ HTTP/1.1" 302 0
/home/dinmarr/learn/django/taskmanager/tasks/admin.py changed, reloading.
Watching for file changes with StatReloader
/home/dinmarr/learn/django/taskmanager/tasks/admin.py changed, reloading.
Watching for file changes with StatReloader
Watching for file changes with StatReloader
/home/dinmarr/learn/django/taskmanager/tasks/admin.py changed, reloading.
Watching for file changes with StatReloader
"GET /admin/auth/user/ HTTP/1.1" 200 11698
"GET /admin/jsi18n/ HTTP/1.1" 200 3342
"GET /static/admin/js/filters.js HTTP/1.1" 200 978
"GET /static/admin/js/jquery.init.js HTTP/1.1" 200 347
Not Found: /favicon.ico
"GET /favicon.ico HTTP/1.1" 404 2699
"GET /admin/tasks/task/ HTTP/1.1" 200 9545
"GET /admin/jsi18n/ HTTP/1.1" 200 3342
Not Found: /favicon.ico
"GET /admin/tasks/task/ HTTP/1.1" 200 9545
"GET /admin/jsi18n/ HTTP/1.1" 200 3342
"GET /admin/tasks/task/add/ HTTP/1.1" 200 10865
"GET /admin/jsi18n/ HTTP/1.1" 200 3342
"GET /static/admin/js/change_form.js HTTP/1.1" 200 606
"GET /static/admin/js/prepopulate_init.js HTTP/1.1" 200 586
"GET /static/admin/css/forms.css HTTP/1.1" 200 8794
"GET /static/admin/css/widgets.css HTTP/1.1" 200 11564
Not Found: /favicon.ico
"POST /admin/tasks/task/add/ HTTP/1.1" 302 0
"GET /admin/tasks/task/ HTTP/1.1" 200 11485
"GET /admin/jsi18n/ HTTP/1.1" 200 3342
"GET /static/admin/img/icon-yes.svg HTTP/1.1" 200 436
"GET /static/admin/img/icon-no.svg HTTP/1.1" 200 560
"GET /static/admin/img/search.svg HTTP/1.1" 200 458
Not Found: /favicon.ico
"GET /favicon.ico HTTP/1.1" 404 2699
"GET /admin/tasks/task/1/change/ HTTP/1.1" 200 11178
"GET /admin/jsi18n/ HTTP/1.1" 200 3342
Not Found: /favicon.ico
"POST /admin/tasks/task/1/change/ HTTP/1.1" 302 0
"GET /admin/tasks/task/ HTTP/1.1" 200 11487
"GET /admin/jsi18n/ HTTP/1.1" 200 3342
Not Found: /favicon.ico
Bad Request: /api/register/
"POST /api/register/ HTTP/1.1" 400 103
"POST /api/register/ HTTP/1.1" 201 323
"POST /api/login/ HTTP/1.1" 200 589
Not Found: /api/lchange-password/
"POST /api/lchange-password/ HTTP/1.1" 404 4207
"POST /api/change-password/ HTTP/1.1" 200 44
Internal Server Error: /api/tasks/
Traceback (most recent call last):
  File "/home/dinmarr/learn/django/myenv/lib/python3.13/site-packages/django/core/handlers/exception.py", line 55, in inner
    response = get_response(request)
  File "/home/dinmarr/learn/django/myenv/lib/python3.13/site-packages/django/core/handlers/base.py", line 197, in _get_response
    response = wrapped_callback(request, *callback_args, **callback_kwargs)
  File "/home/dinmarr/learn/django/myenv/lib/python3.13/site-packages/django/views/decorators/csrf.py", line 65, in _view_wrapper
    return view_func(request, *args, **kwargs)
  File "/home/dinmarr/learn/django/myenv/lib/python3.13/site-packages/django/views/generic/base.py", line 104, in view
    return self.dispatch(request, *args, **kwargs)
           ~~~~~~~~~~~~~^^^^^^^^^^^^^^^^^^^^^^^^^^
  File "/home/dinmarr/learn/django/myenv/lib/python3.13/site-packages/rest_framework/views.py", line 509, in dispatch
    response = self.handle_exception(exc)
  File "/home/dinmarr/learn/django/myenv/lib/python3.13/site-packages/rest_framework/views.py", line 469, in handle_exception
    self.raise_uncaught_exception(exc)
    ~~~~~~~~~~~~~~~~~~~~~~~~~~~~~^^^^^
  File "/home/dinmarr/learn/django/myenv/lib/python3.13/site-packages/rest_framework/views.py", line 480, in raise_uncaught_exception
    raise exc
  File "/home/dinmarr/learn/django/myenv/lib/python3.13/site-packages/rest_framework/views.py", line 506, in dispatch
    response = handler(request, *args, **kwargs)
  File "/home/dinmarr/learn/django/taskmanager/tasks/views.py", line 115, in get
    cached_tasks = cache.get('task_list')
                   ^^^^^
NameError: name 'cache' is not defined
"GET /api/tasks/ HTTP/1.1" 500 99814
/home/dinmarr/learn/django/taskmanager/tasks/views.py changed, reloading.
Watching for file changes with StatReloader
Internal Server Error: /api/tasks/
Traceback (most recent call last):
  File "/home/dinmarr/learn/django/myenv/lib/python3.13/site-packages/django_redis/cache.py", line 29, in _decorator
    return method(self, *args, **kwargs)
  File "/home/dinmarr/learn/django/myenv/lib/python3.13/site-packages/django_redis/cache.py", line 99, in _get
    return self.client.get(key, default=default, version=version, client=client)
           ~~~~~~~~~~~~~~~^^^^^^^^^^^^^^^^^^^^^^^^^^^^^^^^^^^^^^^^^^^^^^^^^^^^^^
  File "/home/dinmarr/learn/django/myenv/lib/python3.13/site-packages/django_redis/client/default.py", line 260, in get
    raise ConnectionInterrupted(connection=client) from e
django_redis.exceptions.ConnectionInterrupted: Redis ConnectionError: Error 111 connecting to 127.0.0.1:6379. Connection refused.

During handling of the above exception, another exception occurred:

Traceback (most recent call last):
  File "/home/dinmarr/learn/django/myenv/lib/python3.13/site-packages/django/core/handlers/exception.py", line 55, in inner
    response = get_response(request)
  File "/home/dinmarr/learn/django/myenv/lib/python3.13/site-packages/django/core/handlers/base.py", line 197, in _get_response
    response = wrapped_callback(request, *callback_args, **callback_kwargs)
  File "/home/dinmarr/learn/django/myenv/lib/python3.13/site-packages/django/views/decorators/csrf.py", line 65, in _view_wrapper
    return view_func(request, *args, **kwargs)
  File "/home/dinmarr/learn/django/myenv/lib/python3.13/site-packages/django/views/generic/base.py", line 104, in view
    return self.dispatch(request, *args, **kwargs)
           ~~~~~~~~~~~~~^^^^^^^^^^^^^^^^^^^^^^^^^^
  File "/home/dinmarr/learn/django/myenv/lib/python3.13/site-packages/rest_framework/views.py", line 509, in dispatch
    response = self.handle_exception(exc)
  File "/home/dinmarr/learn/django/myenv/lib/python3.13/site-packages/rest_framework/views.py", line 469, in handle_exception
    self.raise_uncaught_exception(exc)
    ~~~~~~~~~~~~~~~~~~~~~~~~~~~~~^^^^^
  File "/home/dinmarr/learn/django/myenv/lib/python3.13/site-packages/rest_framework/views.py", line 480, in raise_uncaught_exception
    raise exc
  File "/home/dinmarr/learn/django/myenv/lib/python3.13/site-packages/rest_framework/views.py", line 506, in dispatch
    response = handler(request, *args, **kwargs)
  File "/home/dinmarr/learn/django/taskmanager/tasks/views.py", line 116, in get
    cached_tasks = cache.get('task_list')
  File "/home/dinmarr/learn/django/myenv/lib/python3.13/site-packages/django_redis/cache.py", line 92, in get
    value = self._get(key, default, version, client)
  File "/home/dinmarr/learn/django/myenv/lib/python3.13/site-packages/django_redis/cache.py", line 36, in _decorator
    raise e.__cause__
  File "/home/dinmarr/learn/django/myenv/lib/python3.13/site-packages/django_redis/client/default.py", line 258, in get
    value = client.get(key)
  File "/home/dinmarr/learn/django/myenv/lib/python3.13/site-packages/redis/commands/core.py", line 1822, in get
    return self.execute_command("GET", name, keys=[name])
           ~~~~~~~~~~~~~~~~~~~~^^^^^^^^^^^^^^^^^^^^^^^^^^
  File "/home/dinmarr/learn/django/myenv/lib/python3.13/site-packages/redis/client.py", line 559, in execute_command
    return self._execute_command(*args, **options)
           ~~~~~~~~~~~~~~~~~~~~~^^^^^^^^^^^^^^^^^^
  File "/home/dinmarr/learn/django/myenv/lib/python3.13/site-packages/redis/client.py", line 565, in _execute_command
    conn = self.connection or pool.get_connection(command_name, **options)
                              ~~~~~~~~~~~~~~~~~~~^^^^^^^^^^^^^^^^^^^^^^^^^
  File "/home/dinmarr/learn/django/myenv/lib/python3.13/site-packages/redis/connection.py", line 1422, in get_connection
    connection.connect()
    ~~~~~~~~~~~~~~~~~~^^
  File "/home/dinmarr/learn/django/myenv/lib/python3.13/site-packages/redis/connection.py", line 363, in connect
    raise ConnectionError(self._error_message(e))
redis.exceptions.ConnectionError: Error 111 connecting to 127.0.0.1:6379. Connection refused.
"GET /api/tasks/ HTTP/1.1" 500 149831
Internal Server Error: /api/tasks/
Traceback (most recent call last):
  File "/home/dinmarr/learn/django/myenv/lib/python3.13/site-packages/django/core/handlers/exception.py", line 55, in inner
    response = get_response(request)
  File "/home/dinmarr/learn/django/myenv/lib/python3.13/site-packages/django/core/handlers/base.py", line 197, in _get_response
    response = wrapped_callback(request, *callback_args, **callback_kwargs)
  File "/home/dinmarr/learn/django/myenv/lib/python3.13/site-packages/django/views/decorators/csrf.py", line 65, in _view_wrapper
    return view_func(request, *args, **kwargs)
  File "/home/dinmarr/learn/django/myenv/lib/python3.13/site-packages/django/views/generic/base.py", line 104, in view
    return self.dispatch(request, *args, **kwargs)
           ~~~~~~~~~~~~~^^^^^^^^^^^^^^^^^^^^^^^^^^
  File "/home/dinmarr/learn/django/myenv/lib/python3.13/site-packages/rest_framework/views.py", line 509, in dispatch
    response = self.handle_exception(exc)
  File "/home/dinmarr/learn/django/myenv/lib/python3.13/site-packages/rest_framework/views.py", line 469, in handle_exception
    self.raise_uncaught_exception(exc)
    ~~~~~~~~~~~~~~~~~~~~~~~~~~~~~^^^^^
  File "/home/dinmarr/learn/django/myenv/lib/python3.13/site-packages/rest_framework/views.py", line 480, in raise_uncaught_exception
    raise exc
  File "/home/dinmarr/learn/django/myenv/lib/python3.13/site-packages/rest_framework/views.py", line 506, in dispatch
    response = handler(request, *args, **kwargs)
  File "/home/dinmarr/learn/django/taskmanager/tasks/views.py", line 118, in get
    tasks = Task.objects.filter(user=request.user)
  File "/home/dinmarr/learn/django/myenv/lib/python3.13/site-packages/django/db/models/manager.py", line 87, in manager_method
    return getattr(self.get_queryset(), name)(*args, **kwargs)
           ~~~~~~~~~~~~~~~~~~~~~~~~~~~~~~~~~~^^^^^^^^^^^^^^^^^
  File "/home/dinmarr/learn/django/myenv/lib/python3.13/site-packages/django/db/models/query.py", line 1476, in filter
    return self._filter_or_exclude(False, args, kwargs)
           ~~~~~~~~~~~~~~~~~~~~~~~^^^^^^^^^^^^^^^^^^^^^
  File "/home/dinmarr/learn/django/myenv/lib/python3.13/site-packages/django/db/models/query.py", line 1494, in _filter_or_exclude
    clone._filter_or_exclude_inplace(negate, args, kwargs)
    ~~~~~~~~~~~~~~~~~~~~~~~~~~~~~~~~^^^^^^^^^^^^^^^^^^^^^^
  File "/home/dinmarr/learn/django/myenv/lib/python3.13/site-packages/django/db/models/query.py", line 1501, in _filter_or_exclude_inplace
    self._query.add_q(Q(*args, **kwargs))
    ~~~~~~~~~~~~~~~~~^^^^^^^^^^^^^^^^^^^^
  File "/home/dinmarr/learn/django/myenv/lib/python3.13/site-packages/django/db/models/sql/query.py", line 1609, in add_q
    clause, _ = self._add_q(q_object, self.used_aliases)
                ~~~~~~~~~~~^^^^^^^^^^^^^^^^^^^^^^^^^^^^^
  File "/home/dinmarr/learn/django/myenv/lib/python3.13/site-packages/django/db/models/sql/query.py", line 1641, in _add_q
    child_clause, needed_inner = self.build_filter(
                                 ~~~~~~~~~~~~~~~~~^
        child,
        ^^^^^^
    ...<7 lines>...
        update_join_types=update_join_types,
        ^^^^^^^^^^^^^^^^^^^^^^^^^^^^^^^^^^^^
    )
    ^
  File "/home/dinmarr/learn/django/myenv/lib/python3.13/site-packages/django/db/models/sql/query.py", line 1491, in build_filter
    lookups, parts, reffed_expression = self.solve_lookup_type(arg, summarize)
                                        ~~~~~~~~~~~~~~~~~~~~~~^^^^^^^^^^^^^^^^
  File "/home/dinmarr/learn/django/myenv/lib/python3.13/site-packages/django/db/models/sql/query.py", line 1303, in solve_lookup_type
    _, field, _, lookup_parts = self.names_to_path(lookup_splitted, self.get_meta())
                                ~~~~~~~~~~~~~~~~~~^^^^^^^^^^^^^^^^^^^^^^^^^^^^^^^^^^
  File "/home/dinmarr/learn/django/myenv/lib/python3.13/site-packages/django/db/models/sql/query.py", line 1768, in names_to_path
    raise FieldError(
    ...<2 lines>...
    )
django.core.exceptions.FieldError: Cannot resolve keyword 'user' into field. Choices are: completed, created_at, description, id, title
"GET /api/tasks/ HTTP/1.1" 500 145310
Watching for file changes with StatReloader
Internal Server Error: /api/tasks/
Traceback (most recent call last):
  File "/home/dinmarr/learn/django/myenv/lib/python3.13/site-packages/django_redis/cache.py", line 29, in _decorator
    return method(self, *args, **kwargs)
  File "/home/dinmarr/learn/django/myenv/lib/python3.13/site-packages/django_redis/cache.py", line 99, in _get
    return self.client.get(key, default=default, version=version, client=client)
           ~~~~~~~~~~~~~~~^^^^^^^^^^^^^^^^^^^^^^^^^^^^^^^^^^^^^^^^^^^^^^^^^^^^^^
  File "/home/dinmarr/learn/django/myenv/lib/python3.13/site-packages/django_redis/client/default.py", line 260, in get
    raise ConnectionInterrupted(connection=client) from e
django_redis.exceptions.ConnectionInterrupted: Redis ConnectionError: Error 111 connecting to 127.0.0.1:6379. Connection refused.

During handling of the above exception, another exception occurred:

Traceback (most recent call last):
  File "/home/dinmarr/learn/django/myenv/lib/python3.13/site-packages/django/core/handlers/exception.py", line 55, in inner
    response = get_response(request)
  File "/home/dinmarr/learn/django/myenv/lib/python3.13/site-packages/django/core/handlers/base.py", line 197, in _get_response
    response = wrapped_callback(request, *callback_args, **callback_kwargs)
  File "/home/dinmarr/learn/django/myenv/lib/python3.13/site-packages/django/views/decorators/csrf.py", line 65, in _view_wrapper
    return view_func(request, *args, **kwargs)
  File "/home/dinmarr/learn/django/myenv/lib/python3.13/site-packages/django/views/generic/base.py", line 104, in view
    return self.dispatch(request, *args, **kwargs)
           ~~~~~~~~~~~~~^^^^^^^^^^^^^^^^^^^^^^^^^^
  File "/home/dinmarr/learn/django/myenv/lib/python3.13/site-packages/rest_framework/views.py", line 509, in dispatch
    response = self.handle_exception(exc)
  File "/home/dinmarr/learn/django/myenv/lib/python3.13/site-packages/rest_framework/views.py", line 469, in handle_exception
    self.raise_uncaught_exception(exc)
    ~~~~~~~~~~~~~~~~~~~~~~~~~~~~~^^^^^
  File "/home/dinmarr/learn/django/myenv/lib/python3.13/site-packages/rest_framework/views.py", line 480, in raise_uncaught_exception
    raise exc
  File "/home/dinmarr/learn/django/myenv/lib/python3.13/site-packages/rest_framework/views.py", line 506, in dispatch
    response = handler(request, *args, **kwargs)
  File "/home/dinmarr/learn/django/taskmanager/tasks/views.py", line 116, in get
    cached_tasks = cache.get('task_list')
  File "/home/dinmarr/learn/django/myenv/lib/python3.13/site-packages/django_redis/cache.py", line 92, in get
    value = self._get(key, default, version, client)
  File "/home/dinmarr/learn/django/myenv/lib/python3.13/site-packages/django_redis/cache.py", line 36, in _decorator
    raise e.__cause__
  File "/home/dinmarr/learn/django/myenv/lib/python3.13/site-packages/django_redis/client/default.py", line 258, in get
    value = client.get(key)
  File "/home/dinmarr/learn/django/myenv/lib/python3.13/site-packages/redis/commands/core.py", line 1822, in get
    return self.execute_command("GET", name, keys=[name])
           ~~~~~~~~~~~~~~~~~~~~^^^^^^^^^^^^^^^^^^^^^^^^^^
  File "/home/dinmarr/learn/django/myenv/lib/python3.13/site-packages/redis/client.py", line 559, in execute_command
    return self._execute_command(*args, **options)
           ~~~~~~~~~~~~~~~~~~~~~^^^^^^^^^^^^^^^^^^
  File "/home/dinmarr/learn/django/myenv/lib/python3.13/site-packages/redis/client.py", line 565, in _execute_command
    conn = self.connection or pool.get_connection(command_name, **options)
                              ~~~~~~~~~~~~~~~~~~~^^^^^^^^^^^^^^^^^^^^^^^^^
  File "/home/dinmarr/learn/django/myenv/lib/python3.13/site-packages/redis/connection.py", line 1422, in get_connection
    connection.connect()
    ~~~~~~~~~~~~~~~~~~^^
  File "/home/dinmarr/learn/django/myenv/lib/python3.13/site-packages/redis/connection.py", line 363, in connect
    raise ConnectionError(self._error_message(e))
redis.exceptions.ConnectionError: Error 111 connecting to 127.0.0.1:6379. Connection refused.
"GET /api/tasks/ HTTP/1.1" 500 149833
Internal Server Error: /api/tasks/
Traceback (most recent call last):
  File "/home/dinmarr/learn/django/myenv/lib/python3.13/site-packages/django/core/handlers/exception.py", line 55, in inner
    response = get_response(request)
  File "/home/dinmarr/learn/django/myenv/lib/python3.13/site-packages/django/core/handlers/base.py", line 197, in _get_response
    response = wrapped_callback(request, *callback_args, **callback_kwargs)
  File "/home/dinmarr/learn/django/myenv/lib/python3.13/site-packages/django/views/decorators/csrf.py", line 65, in _view_wrapper
    return view_func(request, *args, **kwargs)
  File "/home/dinmarr/learn/django/myenv/lib/python3.13/site-packages/django/views/generic/base.py", line 104, in view
    return self.dispatch(request, *args, **kwargs)
           ~~~~~~~~~~~~~^^^^^^^^^^^^^^^^^^^^^^^^^^
  File "/home/dinmarr/learn/django/myenv/lib/python3.13/site-packages/rest_framework/views.py", line 509, in dispatch
    response = self.handle_exception(exc)
  File "/home/dinmarr/learn/django/myenv/lib/python3.13/site-packages/rest_framework/views.py", line 469, in handle_exception
    self.raise_uncaught_exception(exc)
    ~~~~~~~~~~~~~~~~~~~~~~~~~~~~~^^^^^
  File "/home/dinmarr/learn/django/myenv/lib/python3.13/site-packages/rest_framework/views.py", line 480, in raise_uncaught_exception
    raise exc
  File "/home/dinmarr/learn/django/myenv/lib/python3.13/site-packages/rest_framework/views.py", line 506, in dispatch
    response = handler(request, *args, **kwargs)
  File "/home/dinmarr/learn/django/taskmanager/tasks/views.py", line 118, in get
    tasks = Task.objects.filter(user=request.user)
  File "/home/dinmarr/learn/django/myenv/lib/python3.13/site-packages/django/db/models/manager.py", line 87, in manager_method
    return getattr(self.get_queryset(), name)(*args, **kwargs)
           ~~~~~~~~~~~~~~~~~~~~~~~~~~~~~~~~~~^^^^^^^^^^^^^^^^^
  File "/home/dinmarr/learn/django/myenv/lib/python3.13/site-packages/django/db/models/query.py", line 1476, in filter
    return self._filter_or_exclude(False, args, kwargs)
           ~~~~~~~~~~~~~~~~~~~~~~~^^^^^^^^^^^^^^^^^^^^^
  File "/home/dinmarr/learn/django/myenv/lib/python3.13/site-packages/django/db/models/query.py", line 1494, in _filter_or_exclude
    clone._filter_or_exclude_inplace(negate, args, kwargs)
    ~~~~~~~~~~~~~~~~~~~~~~~~~~~~~~~~^^^^^^^^^^^^^^^^^^^^^^
  File "/home/dinmarr/learn/django/myenv/lib/python3.13/site-packages/django/db/models/query.py", line 1501, in _filter_or_exclude_inplace
    self._query.add_q(Q(*args, **kwargs))
    ~~~~~~~~~~~~~~~~~^^^^^^^^^^^^^^^^^^^^
  File "/home/dinmarr/learn/django/myenv/lib/python3.13/site-packages/django/db/models/sql/query.py", line 1609, in add_q
    clause, _ = self._add_q(q_object, self.used_aliases)
                ~~~~~~~~~~~^^^^^^^^^^^^^^^^^^^^^^^^^^^^^
  File "/home/dinmarr/learn/django/myenv/lib/python3.13/site-packages/django/db/models/sql/query.py", line 1641, in _add_q
    child_clause, needed_inner = self.build_filter(
                                 ~~~~~~~~~~~~~~~~~^
        child,
        ^^^^^^
    ...<7 lines>...
        update_join_types=update_join_types,
        ^^^^^^^^^^^^^^^^^^^^^^^^^^^^^^^^^^^^
    )
    ^
  File "/home/dinmarr/learn/django/myenv/lib/python3.13/site-packages/django/db/models/sql/query.py", line 1491, in build_filter
    lookups, parts, reffed_expression = self.solve_lookup_type(arg, summarize)
                                        ~~~~~~~~~~~~~~~~~~~~~~^^^^^^^^^^^^^^^^
  File "/home/dinmarr/learn/django/myenv/lib/python3.13/site-packages/django/db/models/sql/query.py", line 1303, in solve_lookup_type
    _, field, _, lookup_parts = self.names_to_path(lookup_splitted, self.get_meta())
                                ~~~~~~~~~~~~~~~~~~^^^^^^^^^^^^^^^^^^^^^^^^^^^^^^^^^^
  File "/home/dinmarr/learn/django/myenv/lib/python3.13/site-packages/django/db/models/sql/query.py", line 1768, in names_to_path
    raise FieldError(
    ...<2 lines>...
    )
django.core.exceptions.FieldError: Cannot resolve keyword 'user' into field. Choices are: completed, created_at, description, id, title
"GET /api/tasks/ HTTP/1.1" 500 145312
/home/dinmarr/learn/django/taskmanager/tasks/models.py changed, reloading.
Watching for file changes with StatReloader
/home/dinmarr/learn/django/taskmanager/tasks/views.py changed, reloading.
Watching for file changes with StatReloader
/home/dinmarr/learn/django/taskmanager/tasks/views.py changed, reloading.
Watching for file changes with StatReloader
/home/dinmarr/learn/django/taskmanager/tasks/views.py changed, reloading.
Watching for file changes with StatReloader
Watching for file changes with StatReloader
Internal Server Error: /api/tasks/
Traceback (most recent call last):
  File "/home/dinmarr/learn/django/myenv/lib/python3.13/site-packages/django/db/backends/utils.py", line 105, in _execute
    return self.cursor.execute(sql, params)
           ~~~~~~~~~~~~~~~~~~~^^^^^^^^^^^^^
psycopg2.errors.UndefinedColumn: column tasks_task.user_id does not exist
LINE 1: SELECT "tasks_task"."id", "tasks_task"."user_id", "tasks_tas...
                                  ^


The above exception was the direct cause of the following exception:

Traceback (most recent call last):
  File "/home/dinmarr/learn/django/myenv/lib/python3.13/site-packages/django/core/handlers/exception.py", line 55, in inner
    response = get_response(request)
  File "/home/dinmarr/learn/django/myenv/lib/python3.13/site-packages/django/core/handlers/base.py", line 197, in _get_response
    response = wrapped_callback(request, *callback_args, **callback_kwargs)
  File "/home/dinmarr/learn/django/myenv/lib/python3.13/site-packages/django/views/decorators/csrf.py", line 65, in _view_wrapper
    return view_func(request, *args, **kwargs)
  File "/home/dinmarr/learn/django/myenv/lib/python3.13/site-packages/django/views/generic/base.py", line 104, in view
    return self.dispatch(request, *args, **kwargs)
           ~~~~~~~~~~~~~^^^^^^^^^^^^^^^^^^^^^^^^^^
  File "/home/dinmarr/learn/django/myenv/lib/python3.13/site-packages/rest_framework/views.py", line 509, in dispatch
    response = self.handle_exception(exc)
  File "/home/dinmarr/learn/django/myenv/lib/python3.13/site-packages/rest_framework/views.py", line 469, in handle_exception
    self.raise_uncaught_exception(exc)
    ~~~~~~~~~~~~~~~~~~~~~~~~~~~~~^^^^^
  File "/home/dinmarr/learn/django/myenv/lib/python3.13/site-packages/rest_framework/views.py", line 480, in raise_uncaught_exception
    raise exc
  File "/home/dinmarr/learn/django/myenv/lib/python3.13/site-packages/rest_framework/views.py", line 506, in dispatch
    response = handler(request, *args, **kwargs)
  File "/home/dinmarr/learn/django/taskmanager/tasks/views.py", line 121, in get
    cache.set(cache_key, serializer.data, timeout=60)
                         ^^^^^^^^^^^^^^^
  File "/home/dinmarr/learn/django/myenv/lib/python3.13/site-packages/rest_framework/serializers.py", line 795, in data
    ret = super().data
          ^^^^^^^^^^^^
  File "/home/dinmarr/learn/django/myenv/lib/python3.13/site-packages/rest_framework/serializers.py", line 249, in data
    self._data = self.to_representation(self.instance)
                 ~~~~~~~~~~~~~~~~~~~~~~^^^^^^^^^^^^^^^
  File "/home/dinmarr/learn/django/myenv/lib/python3.13/site-packages/rest_framework/serializers.py", line 714, in to_representation
    self.child.to_representation(item) for item in iterable
                                                   ^^^^^^^^
  File "/home/dinmarr/learn/django/myenv/lib/python3.13/site-packages/django/db/models/query.py", line 400, in __iter__
    self._fetch_all()
    ~~~~~~~~~~~~~~~^^
  File "/home/dinmarr/learn/django/myenv/lib/python3.13/site-packages/django/db/models/query.py", line 1928, in _fetch_all
    self._result_cache = list(self._iterable_class(self))
                         ~~~~^^^^^^^^^^^^^^^^^^^^^^^^^^^^
  File "/home/dinmarr/learn/django/myenv/lib/python3.13/site-packages/django/db/models/query.py", line 91, in __iter__
    results = compiler.execute_sql(
        chunked_fetch=self.chunked_fetch, chunk_size=self.chunk_size
    )
  File "/home/dinmarr/learn/django/myenv/lib/python3.13/site-packages/django/db/models/sql/compiler.py", line 1574, in execute_sql
    cursor.execute(sql, params)
    ~~~~~~~~~~~~~~^^^^^^^^^^^^^
  File "/home/dinmarr/learn/django/myenv/lib/python3.13/site-packages/django/db/backends/utils.py", line 122, in execute
    return super().execute(sql, params)
           ~~~~~~~~~~~~~~~^^^^^^^^^^^^^
  File "/home/dinmarr/learn/django/myenv/lib/python3.13/site-packages/django/db/backends/utils.py", line 79, in execute
    return self._execute_with_wrappers(
           ~~~~~~~~~~~~~~~~~~~~~~~~~~~^
        sql, params, many=False, executor=self._execute
        ^^^^^^^^^^^^^^^^^^^^^^^^^^^^^^^^^^^^^^^^^^^^^^^
    )
    ^
  File "/home/dinmarr/learn/django/myenv/lib/python3.13/site-packages/django/db/backends/utils.py", line 92, in _execute_with_wrappers
    return executor(sql, params, many, context)
  File "/home/dinmarr/learn/django/myenv/lib/python3.13/site-packages/django/db/backends/utils.py", line 100, in _execute
    with self.db.wrap_database_errors:
         ^^^^^^^^^^^^^^^^^^^^^^^^^^^^
  File "/home/dinmarr/learn/django/myenv/lib/python3.13/site-packages/django/db/utils.py", line 91, in __exit__
    raise dj_exc_value.with_traceback(traceback) from exc_value
  File "/home/dinmarr/learn/django/myenv/lib/python3.13/site-packages/django/db/backends/utils.py", line 105, in _execute
    return self.cursor.execute(sql, params)
           ~~~~~~~~~~~~~~~~~~~^^^^^^^^^^^^^
django.db.utils.ProgrammingError: column tasks_task.user_id does not exist
LINE 1: SELECT "tasks_task"."id", "tasks_task"."user_id", "tasks_tas...
                                  ^

"GET /api/tasks/ HTTP/1.1" 500 169647
Watching for file changes with StatReloader
Unauthorized: /api/tasks/
"GET /api/tasks/ HTTP/1.1" 401 51
"POST /api/register/ HTTP/1.1" 201 323
"POST /api/login/ HTTP/1.1" 200 589
Internal Server Error: /api/tasks/
Traceback (most recent call last):
  File "/home/dinmarr/learn/django/myenv/lib/python3.13/site-packages/django/db/backends/utils.py", line 105, in _execute
    return self.cursor.execute(sql, params)
           ~~~~~~~~~~~~~~~~~~~^^^^^^^^^^^^^
psycopg2.errors.UndefinedColumn: column tasks_task.user_id does not exist
LINE 1: SELECT "tasks_task"."id", "tasks_task"."user_id", "tasks_tas...
                                  ^


The above exception was the direct cause of the following exception:

Traceback (most recent call last):
  File "/home/dinmarr/learn/django/myenv/lib/python3.13/site-packages/django/core/handlers/exception.py", line 55, in inner
    response = get_response(request)
  File "/home/dinmarr/learn/django/myenv/lib/python3.13/site-packages/django/core/handlers/base.py", line 197, in _get_response
    response = wrapped_callback(request, *callback_args, **callback_kwargs)
  File "/home/dinmarr/learn/django/myenv/lib/python3.13/site-packages/django/views/decorators/csrf.py", line 65, in _view_wrapper
    return view_func(request, *args, **kwargs)
  File "/home/dinmarr/learn/django/myenv/lib/python3.13/site-packages/django/views/generic/base.py", line 104, in view
    return self.dispatch(request, *args, **kwargs)
           ~~~~~~~~~~~~~^^^^^^^^^^^^^^^^^^^^^^^^^^
  File "/home/dinmarr/learn/django/myenv/lib/python3.13/site-packages/rest_framework/views.py", line 509, in dispatch
    response = self.handle_exception(exc)
  File "/home/dinmarr/learn/django/myenv/lib/python3.13/site-packages/rest_framework/views.py", line 469, in handle_exception
    self.raise_uncaught_exception(exc)
    ~~~~~~~~~~~~~~~~~~~~~~~~~~~~~^^^^^
  File "/home/dinmarr/learn/django/myenv/lib/python3.13/site-packages/rest_framework/views.py", line 480, in raise_uncaught_exception
    raise exc
  File "/home/dinmarr/learn/django/myenv/lib/python3.13/site-packages/rest_framework/views.py", line 506, in dispatch
    response = handler(request, *args, **kwargs)
  File "/home/dinmarr/learn/django/taskmanager/tasks/views.py", line 121, in get
    cache.set(cache_key, serializer.data, timeout=60)
                         ^^^^^^^^^^^^^^^
  File "/home/dinmarr/learn/django/myenv/lib/python3.13/site-packages/rest_framework/serializers.py", line 795, in data
    ret = super().data
          ^^^^^^^^^^^^
  File "/home/dinmarr/learn/django/myenv/lib/python3.13/site-packages/rest_framework/serializers.py", line 249, in data
    self._data = self.to_representation(self.instance)
                 ~~~~~~~~~~~~~~~~~~~~~~^^^^^^^^^^^^^^^
  File "/home/dinmarr/learn/django/myenv/lib/python3.13/site-packages/rest_framework/serializers.py", line 714, in to_representation
    self.child.to_representation(item) for item in iterable
                                                   ^^^^^^^^
  File "/home/dinmarr/learn/django/myenv/lib/python3.13/site-packages/django/db/models/query.py", line 400, in __iter__
    self._fetch_all()
    ~~~~~~~~~~~~~~~^^
  File "/home/dinmarr/learn/django/myenv/lib/python3.13/site-packages/django/db/models/query.py", line 1928, in _fetch_all
    self._result_cache = list(self._iterable_class(self))
                         ~~~~^^^^^^^^^^^^^^^^^^^^^^^^^^^^
  File "/home/dinmarr/learn/django/myenv/lib/python3.13/site-packages/django/db/models/query.py", line 91, in __iter__
    results = compiler.execute_sql(
        chunked_fetch=self.chunked_fetch, chunk_size=self.chunk_size
    )
  File "/home/dinmarr/learn/django/myenv/lib/python3.13/site-packages/django/db/models/sql/compiler.py", line 1574, in execute_sql
    cursor.execute(sql, params)
    ~~~~~~~~~~~~~~^^^^^^^^^^^^^
  File "/home/dinmarr/learn/django/myenv/lib/python3.13/site-packages/django/db/backends/utils.py", line 122, in execute
    return super().execute(sql, params)
           ~~~~~~~~~~~~~~~^^^^^^^^^^^^^
  File "/home/dinmarr/learn/django/myenv/lib/python3.13/site-packages/django/db/backends/utils.py", line 79, in execute
    return self._execute_with_wrappers(
           ~~~~~~~~~~~~~~~~~~~~~~~~~~~^
        sql, params, many=False, executor=self._execute
        ^^^^^^^^^^^^^^^^^^^^^^^^^^^^^^^^^^^^^^^^^^^^^^^
    )
    ^
  File "/home/dinmarr/learn/django/myenv/lib/python3.13/site-packages/django/db/backends/utils.py", line 92, in _execute_with_wrappers
    return executor(sql, params, many, context)
  File "/home/dinmarr/learn/django/myenv/lib/python3.13/site-packages/django/db/backends/utils.py", line 100, in _execute
    with self.db.wrap_database_errors:
         ^^^^^^^^^^^^^^^^^^^^^^^^^^^^
  File "/home/dinmarr/learn/django/myenv/lib/python3.13/site-packages/django/db/utils.py", line 91, in __exit__
    raise dj_exc_value.with_traceback(traceback) from exc_value
  File "/home/dinmarr/learn/django/myenv/lib/python3.13/site-packages/django/db/backends/utils.py", line 105, in _execute
    return self.cursor.execute(sql, params)
           ~~~~~~~~~~~~~~~~~~~^^^^^^^^^^^^^
django.db.utils.ProgrammingError: column tasks_task.user_id does not exist
LINE 1: SELECT "tasks_task"."id", "tasks_task"."user_id", "tasks_tas...
                                  ^

"GET /api/tasks/ HTTP/1.1" 500 169647
/home/dinmarr/learn/django/taskmanager/tasks/serializers.py changed, reloading.
Watching for file changes with StatReloader
"GET /admin/ HTTP/1.1" 302 0
"GET /admin/login/?next=/admin/ HTTP/1.1" 200 4160
"GET /static/admin/css/login.css HTTP/1.1" 200 951
"GET /static/admin/css/dark_mode.css HTTP/1.1" 200 2804
"GET /static/admin/css/nav_sidebar.css HTTP/1.1" 200 2810
"GET /static/admin/css/responsive.css HTTP/1.1" 200 17972
"GET /static/admin/css/base.css HTTP/1.1" 200 22092
"GET /static/admin/js/theme.js HTTP/1.1" 304 0
"GET /static/admin/js/nav_sidebar.js HTTP/1.1" 304 0
Not Found: /favicon.ico
"POST /admin/login/?next=/admin/ HTTP/1.1" 200 4323
Not Found: /favicon.ico
"POST /admin/login/?next=/admin/ HTTP/1.1" 302 0
"GET /admin/ HTTP/1.1" 200 6645
"GET /static/admin/css/dashboard.css HTTP/1.1" 200 441
"GET /static/admin/img/icon-addlink.svg HTTP/1.1" 200 331
"GET /static/admin/img/icon-changelink.svg HTTP/1.1" 200 380
Internal Server Error: /admin/tasks/task/
Traceback (most recent call last):
  File "/home/dinmarr/learn/django/myenv/lib/python3.13/site-packages/django/db/backends/utils.py", line 105, in _execute
    return self.cursor.execute(sql, params)
           ~~~~~~~~~~~~~~~~~~~^^^^^^^^^^^^^
psycopg2.errors.UndefinedColumn: column tasks_task.user_id does not exist
LINE 1: SELECT "tasks_task"."id", "tasks_task"."user_id", "tasks_tas...
                                  ^


The above exception was the direct cause of the following exception:

Traceback (most recent call last):
  File "/home/dinmarr/learn/django/myenv/lib/python3.13/site-packages/django/core/handlers/exception.py", line 55, in inner
    response = get_response(request)
  File "/home/dinmarr/learn/django/myenv/lib/python3.13/site-packages/django/core/handlers/base.py", line 197, in _get_response
    response = wrapped_callback(request, *callback_args, **callback_kwargs)
  File "/home/dinmarr/learn/django/myenv/lib/python3.13/site-packages/django/contrib/admin/options.py", line 718, in wrapper
    return self.admin_site.admin_view(view)(*args, **kwargs)
           ~~~~~~~~~~~~~~~~~~~~~~~~~~~~~~~~^^^^^^^^^^^^^^^^^
  File "/home/dinmarr/learn/django/myenv/lib/python3.13/site-packages/django/utils/decorators.py", line 188, in _view_wrapper
    result = _process_exception(request, e)
  File "/home/dinmarr/learn/django/myenv/lib/python3.13/site-packages/django/utils/decorators.py", line 186, in _view_wrapper
    response = view_func(request, *args, **kwargs)
  File "/home/dinmarr/learn/django/myenv/lib/python3.13/site-packages/django/views/decorators/cache.py", line 80, in _view_wrapper
    response = view_func(request, *args, **kwargs)
  File "/home/dinmarr/learn/django/myenv/lib/python3.13/site-packages/django/contrib/admin/sites.py", line 241, in inner
    return view(request, *args, **kwargs)
  File "/home/dinmarr/learn/django/myenv/lib/python3.13/site-packages/django/utils/decorators.py", line 48, in _wrapper
    return bound_method(*args, **kwargs)
  File "/home/dinmarr/learn/django/myenv/lib/python3.13/site-packages/django/utils/decorators.py", line 188, in _view_wrapper
    result = _process_exception(request, e)
  File "/home/dinmarr/learn/django/myenv/lib/python3.13/site-packages/django/utils/decorators.py", line 186, in _view_wrapper
    response = view_func(request, *args, **kwargs)
  File "/home/dinmarr/learn/django/myenv/lib/python3.13/site-packages/django/contrib/admin/options.py", line 2138, in changelist_view
    "selection_note": _("0 of %(cnt)s selected") % {"cnt": len(cl.result_list)},
                                                           ~~~^^^^^^^^^^^^^^^^
  File "/home/dinmarr/learn/django/myenv/lib/python3.13/site-packages/django/db/models/query.py", line 382, in __len__
    self._fetch_all()
    ~~~~~~~~~~~~~~~^^
  File "/home/dinmarr/learn/django/myenv/lib/python3.13/site-packages/django/db/models/query.py", line 1928, in _fetch_all
    self._result_cache = list(self._iterable_class(self))
                         ~~~~^^^^^^^^^^^^^^^^^^^^^^^^^^^^
  File "/home/dinmarr/learn/django/myenv/lib/python3.13/site-packages/django/db/models/query.py", line 91, in __iter__
    results = compiler.execute_sql(
        chunked_fetch=self.chunked_fetch, chunk_size=self.chunk_size
    )
  File "/home/dinmarr/learn/django/myenv/lib/python3.13/site-packages/django/db/models/sql/compiler.py", line 1574, in execute_sql
    cursor.execute(sql, params)
    ~~~~~~~~~~~~~~^^^^^^^^^^^^^
  File "/home/dinmarr/learn/django/myenv/lib/python3.13/site-packages/django/db/backends/utils.py", line 122, in execute
    return super().execute(sql, params)
           ~~~~~~~~~~~~~~~^^^^^^^^^^^^^
  File "/home/dinmarr/learn/django/myenv/lib/python3.13/site-packages/django/db/backends/utils.py", line 79, in execute
    return self._execute_with_wrappers(
           ~~~~~~~~~~~~~~~~~~~~~~~~~~~^
        sql, params, many=False, executor=self._execute
        ^^^^^^^^^^^^^^^^^^^^^^^^^^^^^^^^^^^^^^^^^^^^^^^
    )
    ^
  File "/home/dinmarr/learn/django/myenv/lib/python3.13/site-packages/django/db/backends/utils.py", line 92, in _execute_with_wrappers
    return executor(sql, params, many, context)
  File "/home/dinmarr/learn/django/myenv/lib/python3.13/site-packages/django/db/backends/utils.py", line 100, in _execute
    with self.db.wrap_database_errors:
         ^^^^^^^^^^^^^^^^^^^^^^^^^^^^
  File "/home/dinmarr/learn/django/myenv/lib/python3.13/site-packages/django/db/utils.py", line 91, in __exit__
    raise dj_exc_value.with_traceback(traceback) from exc_value
  File "/home/dinmarr/learn/django/myenv/lib/python3.13/site-packages/django/db/backends/utils.py", line 105, in _execute
    return self.cursor.execute(sql, params)
           ~~~~~~~~~~~~~~~~~~~^^^^^^^^^^^^^
django.db.utils.ProgrammingError: column tasks_task.user_id does not exist
LINE 1: SELECT "tasks_task"."id", "tasks_task"."user_id", "tasks_tas...
                                  ^

"GET /admin/tasks/task/ HTTP/1.1" 500 173005
Not Found: /favicon.ico
"GET /admin/ HTTP/1.1" 302 0
/home/dinmarr/learn/django/taskmanager/tasks/admin.py changed, reloading.
Watching for file changes with StatReloader
"GET /admin/ HTTP/1.1" 200 6645
Internal Server Error: /admin/tasks/task/
Traceback (most recent call last):
  File "/home/dinmarr/learn/django/myenv/lib/python3.13/site-packages/django/db/backends/utils.py", line 105, in _execute
    return self.cursor.execute(sql, params)
           ~~~~~~~~~~~~~~~~~~~^^^^^^^^^^^^^
psycopg2.errors.UndefinedColumn: column tasks_task.user_id does not exist
LINE 1: ...ned" FROM "tasks_task" INNER JOIN "auth_user" ON ("tasks_tas...
                                                             ^


The above exception was the direct cause of the following exception:

Traceback (most recent call last):
  File "/home/dinmarr/learn/django/myenv/lib/python3.13/site-packages/django/core/handlers/exception.py", line 55, in inner
    response = get_response(request)
  File "/home/dinmarr/learn/django/myenv/lib/python3.13/site-packages/django/core/handlers/base.py", line 197, in _get_response
    response = wrapped_callback(request, *callback_args, **callback_kwargs)
  File "/home/dinmarr/learn/django/myenv/lib/python3.13/site-packages/django/contrib/admin/options.py", line 718, in wrapper
    return self.admin_site.admin_view(view)(*args, **kwargs)
           ~~~~~~~~~~~~~~~~~~~~~~~~~~~~~~~~^^^^^^^^^^^^^^^^^
  File "/home/dinmarr/learn/django/myenv/lib/python3.13/site-packages/django/utils/decorators.py", line 188, in _view_wrapper
    result = _process_exception(request, e)
  File "/home/dinmarr/learn/django/myenv/lib/python3.13/site-packages/django/utils/decorators.py", line 186, in _view_wrapper
    response = view_func(request, *args, **kwargs)
  File "/home/dinmarr/learn/django/myenv/lib/python3.13/site-packages/django/views/decorators/cache.py", line 80, in _view_wrapper
    response = view_func(request, *args, **kwargs)
  File "/home/dinmarr/learn/django/myenv/lib/python3.13/site-packages/django/contrib/admin/sites.py", line 241, in inner
    return view(request, *args, **kwargs)
  File "/home/dinmarr/learn/django/myenv/lib/python3.13/site-packages/django/utils/decorators.py", line 48, in _wrapper
    return bound_method(*args, **kwargs)
  File "/home/dinmarr/learn/django/myenv/lib/python3.13/site-packages/django/utils/decorators.py", line 188, in _view_wrapper
    result = _process_exception(request, e)
  File "/home/dinmarr/learn/django/myenv/lib/python3.13/site-packages/django/utils/decorators.py", line 186, in _view_wrapper
    response = view_func(request, *args, **kwargs)
  File "/home/dinmarr/learn/django/myenv/lib/python3.13/site-packages/django/contrib/admin/options.py", line 2138, in changelist_view
    "selection_note": _("0 of %(cnt)s selected") % {"cnt": len(cl.result_list)},
                                                           ~~~^^^^^^^^^^^^^^^^
  File "/home/dinmarr/learn/django/myenv/lib/python3.13/site-packages/django/db/models/query.py", line 382, in __len__
    self._fetch_all()
    ~~~~~~~~~~~~~~~^^
  File "/home/dinmarr/learn/django/myenv/lib/python3.13/site-packages/django/db/models/query.py", line 1928, in _fetch_all
    self._result_cache = list(self._iterable_class(self))
                         ~~~~^^^^^^^^^^^^^^^^^^^^^^^^^^^^
  File "/home/dinmarr/learn/django/myenv/lib/python3.13/site-packages/django/db/models/query.py", line 91, in __iter__
    results = compiler.execute_sql(
        chunked_fetch=self.chunked_fetch, chunk_size=self.chunk_size
    )
  File "/home/dinmarr/learn/django/myenv/lib/python3.13/site-packages/django/db/models/sql/compiler.py", line 1574, in execute_sql
    cursor.execute(sql, params)
    ~~~~~~~~~~~~~~^^^^^^^^^^^^^
  File "/home/dinmarr/learn/django/myenv/lib/python3.13/site-packages/django/db/backends/utils.py", line 122, in execute
    return super().execute(sql, params)
           ~~~~~~~~~~~~~~~^^^^^^^^^^^^^
  File "/home/dinmarr/learn/django/myenv/lib/python3.13/site-packages/django/db/backends/utils.py", line 79, in execute
    return self._execute_with_wrappers(
           ~~~~~~~~~~~~~~~~~~~~~~~~~~~^
        sql, params, many=False, executor=self._execute
        ^^^^^^^^^^^^^^^^^^^^^^^^^^^^^^^^^^^^^^^^^^^^^^^
    )
    ^
  File "/home/dinmarr/learn/django/myenv/lib/python3.13/site-packages/django/db/backends/utils.py", line 92, in _execute_with_wrappers
    return executor(sql, params, many, context)
  File "/home/dinmarr/learn/django/myenv/lib/python3.13/site-packages/django/db/backends/utils.py", line 100, in _execute
    with self.db.wrap_database_errors:
         ^^^^^^^^^^^^^^^^^^^^^^^^^^^^
  File "/home/dinmarr/learn/django/myenv/lib/python3.13/site-packages/django/db/utils.py", line 91, in __exit__
    raise dj_exc_value.with_traceback(traceback) from exc_value
  File "/home/dinmarr/learn/django/myenv/lib/python3.13/site-packages/django/db/backends/utils.py", line 105, in _execute
    return self.cursor.execute(sql, params)
           ~~~~~~~~~~~~~~~~~~~^^^^^^^^^^^^^
django.db.utils.ProgrammingError: column tasks_task.user_id does not exist
LINE 1: ...ned" FROM "tasks_task" INNER JOIN "auth_user" ON ("tasks_tas...
                                                             ^

"GET /admin/tasks/task/ HTTP/1.1" 500 177916
"GET /api/tasks/ HTTP/1.1" 200 2
Bad Request: /api/tasks/
"POST /api/tasks/ HTTP/1.1" 400 36
Bad Request: /api/tasks/
"POST /api/tasks/ HTTP/1.1" 400 61
Internal Server Error: /api/tasks/
Traceback (most recent call last):
  File "/home/dinmarr/learn/django/myenv/lib/python3.13/site-packages/kombu/utils/functional.py", line 32, in __call__
    return self.__value__
           ^^^^^^^^^^^^^^
AttributeError: 'ChannelPromise' object has no attribute '__value__'. Did you mean: '__call__'?

During handling of the above exception, another exception occurred:

Traceback (most recent call last):
  File "/home/dinmarr/learn/django/myenv/lib/python3.13/site-packages/kombu/connection.py", line 472, in _reraise_as_library_errors
    yield
  File "/home/dinmarr/learn/django/myenv/lib/python3.13/site-packages/kombu/connection.py", line 459, in _ensure_connection
    return retry_over_time(
        self._connection_factory, self.recoverable_connection_errors,
    ...<2 lines>...
        callback, timeout=timeout
    )
  File "/home/dinmarr/learn/django/myenv/lib/python3.13/site-packages/kombu/utils/functional.py", line 318, in retry_over_time
    return fun(*args, **kwargs)
  File "/home/dinmarr/learn/django/myenv/lib/python3.13/site-packages/kombu/connection.py", line 938, in _connection_factory
    self._connection = self._establish_connection()
                       ~~~~~~~~~~~~~~~~~~~~~~~~~~^^
  File "/home/dinmarr/learn/django/myenv/lib/python3.13/site-packages/kombu/connection.py", line 860, in _establish_connection
    conn = self.transport.establish_connection()
  File "/home/dinmarr/learn/django/myenv/lib/python3.13/site-packages/kombu/transport/pyamqp.py", line 203, in establish_connection
    conn.connect()
    ~~~~~~~~~~~~^^
  File "/home/dinmarr/learn/django/myenv/lib/python3.13/site-packages/amqp/connection.py", line 324, in connect
    self.transport.connect()
    ~~~~~~~~~~~~~~~~~~~~~~^^
  File "/home/dinmarr/learn/django/myenv/lib/python3.13/site-packages/amqp/transport.py", line 132, in connect
    self._connect(self.host, self.port, self.connect_timeout)
    ~~~~~~~~~~~~~^^^^^^^^^^^^^^^^^^^^^^^^^^^^^^^^^^^^^^^^^^^^
  File "/home/dinmarr/learn/django/myenv/lib/python3.13/site-packages/amqp/transport.py", line 187, in _connect
    self.sock.connect(sa)
    ~~~~~~~~~~~~~~~~~^^^^
ConnectionRefusedError: [Errno 111] Connection refused

The above exception was the direct cause of the following exception:

Traceback (most recent call last):
  File "/home/dinmarr/learn/django/myenv/lib/python3.13/site-packages/django/core/handlers/exception.py", line 55, in inner
    response = get_response(request)
  File "/home/dinmarr/learn/django/myenv/lib/python3.13/site-packages/django/core/handlers/base.py", line 197, in _get_response
    response = wrapped_callback(request, *callback_args, **callback_kwargs)
  File "/home/dinmarr/learn/django/myenv/lib/python3.13/site-packages/django/views/decorators/csrf.py", line 65, in _view_wrapper
    return view_func(request, *args, **kwargs)
  File "/home/dinmarr/learn/django/myenv/lib/python3.13/site-packages/django/views/generic/base.py", line 104, in view
    return self.dispatch(request, *args, **kwargs)
           ~~~~~~~~~~~~~^^^^^^^^^^^^^^^^^^^^^^^^^^
  File "/home/dinmarr/learn/django/myenv/lib/python3.13/site-packages/rest_framework/views.py", line 509, in dispatch
    response = self.handle_exception(exc)
  File "/home/dinmarr/learn/django/myenv/lib/python3.13/site-packages/rest_framework/views.py", line 469, in handle_exception
    self.raise_uncaught_exception(exc)
    ~~~~~~~~~~~~~~~~~~~~~~~~~~~~~^^^^^
  File "/home/dinmarr/learn/django/myenv/lib/python3.13/site-packages/rest_framework/views.py", line 480, in raise_uncaught_exception
    raise exc
  File "/home/dinmarr/learn/django/myenv/lib/python3.13/site-packages/rest_framework/views.py", line 506, in dispatch
    response = handler(request, *args, **kwargs)
  File "/home/dinmarr/learn/django/taskmanager/tasks/views.py", line 129, in post
    send_task_notification.delay(serializer.data['title'])
    ~~~~~~~~~~~~~~~~~~~~~~~~~~~~^^^^^^^^^^^^^^^^^^^^^^^^^^
  File "/home/dinmarr/learn/django/myenv/lib/python3.13/site-packages/celery/app/task.py", line 444, in delay
    return self.apply_async(args, kwargs)
           ~~~~~~~~~~~~~~~~^^^^^^^^^^^^^^
  File "/home/dinmarr/learn/django/myenv/lib/python3.13/site-packages/celery/app/task.py", line 594, in apply_async
    return app.send_task(
           ~~~~~~~~~~~~~^
        self.name, args, kwargs, task_id=task_id, producer=producer,
        ^^^^^^^^^^^^^^^^^^^^^^^^^^^^^^^^^^^^^^^^^^^^^^^^^^^^^^^^^^^^
    ...<2 lines>...
        **options
        ^^^^^^^^^
    )
    ^
  File "/home/dinmarr/learn/django/myenv/lib/python3.13/site-packages/celery/app/base.py", line 801, in send_task
    amqp.send_task_message(P, name, message, **options)
    ~~~~~~~~~~~~~~~~~~~~~~^^^^^^^^^^^^^^^^^^^^^^^^^^^^^
  File "/home/dinmarr/learn/django/myenv/lib/python3.13/site-packages/celery/app/amqp.py", line 518, in send_task_message
    ret = producer.publish(
        body,
    ...<7 lines>...
        **properties
    )
  File "/home/dinmarr/learn/django/myenv/lib/python3.13/site-packages/kombu/messaging.py", line 190, in publish
    return _publish(
        body, priority, content_type, content_encoding,
        headers, properties, routing_key, mandatory, immediate,
        exchange_name, declare, timeout, confirm_timeout, retry, retry_policy
    )
  File "/home/dinmarr/learn/django/myenv/lib/python3.13/site-packages/kombu/connection.py", line 556, in _ensured
    return fun(*args, **kwargs)
  File "/home/dinmarr/learn/django/myenv/lib/python3.13/site-packages/kombu/messaging.py", line 200, in _publish
    channel = self.channel
              ^^^^^^^^^^^^
  File "/home/dinmarr/learn/django/myenv/lib/python3.13/site-packages/kombu/messaging.py", line 224, in _get_channel
    channel = self._channel = channel()
                              ~~~~~~~^^
  File "/home/dinmarr/learn/django/myenv/lib/python3.13/site-packages/kombu/utils/functional.py", line 34, in __call__
    value = self.__value__ = self.__contract__()
                             ~~~~~~~~~~~~~~~~~^^
  File "/home/dinmarr/learn/django/myenv/lib/python3.13/site-packages/kombu/messaging.py", line 240, in <lambda>
    channel = ChannelPromise(lambda: connection.default_channel)
                                     ^^^^^^^^^^^^^^^^^^^^^^^^^^
  File "/home/dinmarr/learn/django/myenv/lib/python3.13/site-packages/kombu/connection.py", line 957, in default_channel
    self._ensure_connection(**conn_opts)
    ~~~~~~~~~~~~~~~~~~~~~~~^^^^^^^^^^^^^
  File "/home/dinmarr/learn/django/myenv/lib/python3.13/site-packages/kombu/connection.py", line 458, in _ensure_connection
    with ctx():
         ~~~^^
  File "/usr/lib/python3.13/contextlib.py", line 162, in __exit__
    self.gen.throw(value)
    ~~~~~~~~~~~~~~^^^^^^^
  File "/home/dinmarr/learn/django/myenv/lib/python3.13/site-packages/kombu/connection.py", line 476, in _reraise_as_library_errors
    raise ConnectionError(str(exc)) from exc
kombu.exceptions.OperationalError: [Errno 111] Connection refused
"POST /api/tasks/ HTTP/1.1" 500 244065
/home/dinmarr/learn/django/taskmanager/taskmanager/__init__.py changed, reloading.
Watching for file changes with StatReloader
Internal Server Error: /api/tasks/
Traceback (most recent call last):
  File "/home/dinmarr/learn/django/myenv/lib/python3.13/site-packages/kombu/utils/functional.py", line 32, in __call__
    return self.__value__
           ^^^^^^^^^^^^^^
AttributeError: 'ChannelPromise' object has no attribute '__value__'. Did you mean: '__call__'?

During handling of the above exception, another exception occurred:

Traceback (most recent call last):
  File "/home/dinmarr/learn/django/myenv/lib/python3.13/site-packages/kombu/connection.py", line 472, in _reraise_as_library_errors
    yield
  File "/home/dinmarr/learn/django/myenv/lib/python3.13/site-packages/kombu/connection.py", line 459, in _ensure_connection
    return retry_over_time(
        self._connection_factory, self.recoverable_connection_errors,
    ...<2 lines>...
        callback, timeout=timeout
    )
  File "/home/dinmarr/learn/django/myenv/lib/python3.13/site-packages/kombu/utils/functional.py", line 318, in retry_over_time
    return fun(*args, **kwargs)
  File "/home/dinmarr/learn/django/myenv/lib/python3.13/site-packages/kombu/connection.py", line 938, in _connection_factory
    self._connection = self._establish_connection()
                       ~~~~~~~~~~~~~~~~~~~~~~~~~~^^
  File "/home/dinmarr/learn/django/myenv/lib/python3.13/site-packages/kombu/connection.py", line 860, in _establish_connection
    conn = self.transport.establish_connection()
  File "/home/dinmarr/learn/django/myenv/lib/python3.13/site-packages/kombu/transport/pyamqp.py", line 203, in establish_connection
    conn.connect()
    ~~~~~~~~~~~~^^
  File "/home/dinmarr/learn/django/myenv/lib/python3.13/site-packages/amqp/connection.py", line 324, in connect
    self.transport.connect()
    ~~~~~~~~~~~~~~~~~~~~~~^^
  File "/home/dinmarr/learn/django/myenv/lib/python3.13/site-packages/amqp/transport.py", line 132, in connect
    self._connect(self.host, self.port, self.connect_timeout)
    ~~~~~~~~~~~~~^^^^^^^^^^^^^^^^^^^^^^^^^^^^^^^^^^^^^^^^^^^^
  File "/home/dinmarr/learn/django/myenv/lib/python3.13/site-packages/amqp/transport.py", line 187, in _connect
    self.sock.connect(sa)
    ~~~~~~~~~~~~~~~~~^^^^
ConnectionRefusedError: [Errno 111] Connection refused

The above exception was the direct cause of the following exception:

Traceback (most recent call last):
  File "/home/dinmarr/learn/django/myenv/lib/python3.13/site-packages/django/core/handlers/exception.py", line 55, in inner
    response = get_response(request)
  File "/home/dinmarr/learn/django/myenv/lib/python3.13/site-packages/django/core/handlers/base.py", line 197, in _get_response
    response = wrapped_callback(request, *callback_args, **callback_kwargs)
  File "/home/dinmarr/learn/django/myenv/lib/python3.13/site-packages/django/views/decorators/csrf.py", line 65, in _view_wrapper
    return view_func(request, *args, **kwargs)
  File "/home/dinmarr/learn/django/myenv/lib/python3.13/site-packages/django/views/generic/base.py", line 104, in view
    return self.dispatch(request, *args, **kwargs)
           ~~~~~~~~~~~~~^^^^^^^^^^^^^^^^^^^^^^^^^^
  File "/home/dinmarr/learn/django/myenv/lib/python3.13/site-packages/rest_framework/views.py", line 509, in dispatch
    response = self.handle_exception(exc)
  File "/home/dinmarr/learn/django/myenv/lib/python3.13/site-packages/rest_framework/views.py", line 469, in handle_exception
    self.raise_uncaught_exception(exc)
    ~~~~~~~~~~~~~~~~~~~~~~~~~~~~~^^^^^
  File "/home/dinmarr/learn/django/myenv/lib/python3.13/site-packages/rest_framework/views.py", line 480, in raise_uncaught_exception
    raise exc
  File "/home/dinmarr/learn/django/myenv/lib/python3.13/site-packages/rest_framework/views.py", line 506, in dispatch
    response = handler(request, *args, **kwargs)
  File "/home/dinmarr/learn/django/taskmanager/tasks/views.py", line 129, in post
    send_task_notification.delay(serializer.data['title'])
    ~~~~~~~~~~~~~~~~~~~~~~~~~~~~^^^^^^^^^^^^^^^^^^^^^^^^^^
  File "/home/dinmarr/learn/django/myenv/lib/python3.13/site-packages/celery/app/task.py", line 444, in delay
    return self.apply_async(args, kwargs)
           ~~~~~~~~~~~~~~~~^^^^^^^^^^^^^^
  File "/home/dinmarr/learn/django/myenv/lib/python3.13/site-packages/celery/app/task.py", line 594, in apply_async
    return app.send_task(
           ~~~~~~~~~~~~~^
        self.name, args, kwargs, task_id=task_id, producer=producer,
        ^^^^^^^^^^^^^^^^^^^^^^^^^^^^^^^^^^^^^^^^^^^^^^^^^^^^^^^^^^^^
    ...<2 lines>...
        **options
        ^^^^^^^^^
    )
    ^
  File "/home/dinmarr/learn/django/myenv/lib/python3.13/site-packages/celery/app/base.py", line 801, in send_task
    amqp.send_task_message(P, name, message, **options)
    ~~~~~~~~~~~~~~~~~~~~~~^^^^^^^^^^^^^^^^^^^^^^^^^^^^^
  File "/home/dinmarr/learn/django/myenv/lib/python3.13/site-packages/celery/app/amqp.py", line 518, in send_task_message
    ret = producer.publish(
        body,
    ...<7 lines>...
        **properties
    )
  File "/home/dinmarr/learn/django/myenv/lib/python3.13/site-packages/kombu/messaging.py", line 190, in publish
    return _publish(
        body, priority, content_type, content_encoding,
        headers, properties, routing_key, mandatory, immediate,
        exchange_name, declare, timeout, confirm_timeout, retry, retry_policy
    )
  File "/home/dinmarr/learn/django/myenv/lib/python3.13/site-packages/kombu/connection.py", line 556, in _ensured
    return fun(*args, **kwargs)
  File "/home/dinmarr/learn/django/myenv/lib/python3.13/site-packages/kombu/messaging.py", line 200, in _publish
    channel = self.channel
              ^^^^^^^^^^^^
  File "/home/dinmarr/learn/django/myenv/lib/python3.13/site-packages/kombu/messaging.py", line 224, in _get_channel
    channel = self._channel = channel()
                              ~~~~~~~^^
  File "/home/dinmarr/learn/django/myenv/lib/python3.13/site-packages/kombu/utils/functional.py", line 34, in __call__
    value = self.__value__ = self.__contract__()
                             ~~~~~~~~~~~~~~~~~^^
  File "/home/dinmarr/learn/django/myenv/lib/python3.13/site-packages/kombu/messaging.py", line 240, in <lambda>
    channel = ChannelPromise(lambda: connection.default_channel)
                                     ^^^^^^^^^^^^^^^^^^^^^^^^^^
  File "/home/dinmarr/learn/django/myenv/lib/python3.13/site-packages/kombu/connection.py", line 957, in default_channel
    self._ensure_connection(**conn_opts)
    ~~~~~~~~~~~~~~~~~~~~~~~^^^^^^^^^^^^^
  File "/home/dinmarr/learn/django/myenv/lib/python3.13/site-packages/kombu/connection.py", line 458, in _ensure_connection
    with ctx():
         ~~~^^
  File "/usr/lib/python3.13/contextlib.py", line 162, in __exit__
    self.gen.throw(value)
    ~~~~~~~~~~~~~~^^^^^^^
  File "/home/dinmarr/learn/django/myenv/lib/python3.13/site-packages/kombu/connection.py", line 476, in _reraise_as_library_errors
    raise ConnectionError(str(exc)) from exc
kombu.exceptions.OperationalError: [Errno 111] Connection refused
"POST /api/tasks/ HTTP/1.1" 500 244065
/home/dinmarr/learn/django/taskmanager/taskmanager/__init__.py changed, reloading.
Watching for file changes with StatReloader
"POST /api/tasks/ HTTP/1.1" 201 161
"GET /api/tasks/ HTTP/1.1" 200 487
Not Found: /api/tasks/1/
"GET /api/tasks/1/ HTTP/1.1" 404 4179
Not Found: /api/task-detail/1/
"GET /api/task-detail/1/ HTTP/1.1" 404 4197
"GET /api/task-detail/1 HTTP/1.1" 200 161
/home/dinmarr/learn/django/taskmanager/tasks/urls.py changed, reloading.
Watching for file changes with StatReloader
"GET /api/task-detail/1/ HTTP/1.1" 200 161
"PUT /api/task-detail/1/ HTTP/1.1" 200 160
"GET /api/task-detail/1/ HTTP/1.1" 200 160
"DELETE /api/task-detail/2/ HTTP/1.1" 204 0
"GET /api/tasks/ HTTP/1.1" 200 324
/home/dinmarr/learn/django/taskmanager/tasks/views.py changed, reloading.
Watching for file changes with StatReloader
"DELETE /api/task-detail/3/ HTTP/1.1" 204 38
"GET /admin/ HTTP/1.1" 200 6645
"GET /admin/tasks/task/ HTTP/1.1" 200 11747
"GET /static/admin/img/icon-yes.svg HTTP/1.1" 200 436
"GET /static/admin/css/changelists.css HTTP/1.1" 200 6878
"GET /static/admin/img/search.svg HTTP/1.1" 200 458
"GET /static/admin/js/filters.js HTTP/1.1" 200 978
"GET /static/admin/js/jquery.init.js HTTP/1.1" 200 347
"GET /static/admin/js/vendor/jquery/jquery.js HTTP/1.1" 304 0
"GET /admin/jsi18n/ HTTP/1.1" 200 3342
"GET /static/admin/js/core.js HTTP/1.1" 304 0
"GET /static/admin/js/urlify.js HTTP/1.1" 304 0
"GET /static/admin/js/actions.js HTTP/1.1" 304 0
"GET /static/admin/js/prepopulate.js HTTP/1.1" 304 0
"GET /static/admin/js/admin/RelatedObjectLookups.js HTTP/1.1" 304 0
"GET /static/admin/js/vendor/xregexp/xregexp.js HTTP/1.1" 304 0
"GET /static/admin/img/icon-viewlink.svg HTTP/1.1" 200 581
"GET /static/admin/img/tooltag-add.svg HTTP/1.1" 200 331
Watching for file changes with StatReloader
"GET /admin/tasks/task/ HTTP/1.1" 200 11747
"GET /static/admin/css/base.css HTTP/1.1" 304 0
"GET /static/admin/css/changelists.css HTTP/1.1" 304 0
"GET /static/admin/css/dark_mode.css HTTP/1.1" 304 0
"GET /static/admin/js/theme.js HTTP/1.1" 304 0
"GET /static/admin/css/nav_sidebar.css HTTP/1.1" 304 0
"GET /static/admin/js/vendor/jquery/jquery.js HTTP/1.1" 304 0
"GET /static/admin/js/jquery.init.js HTTP/1.1" 304 0
"GET /static/admin/js/core.js HTTP/1.1" 304 0
"GET /static/admin/js/admin/RelatedObjectLookups.js HTTP/1.1" 304 0
"GET /static/admin/js/actions.js HTTP/1.1" 304 0
"GET /static/admin/img/search.svg HTTP/1.1" 200 458
"GET /static/admin/js/urlify.js HTTP/1.1" 304 0
"GET /static/admin/img/icon-yes.svg HTTP/1.1" 200 436
"GET /static/admin/js/prepopulate.js HTTP/1.1" 304 0
"GET /static/admin/js/vendor/xregexp/xregexp.js HTTP/1.1" 304 0
"GET /static/admin/css/responsive.css HTTP/1.1" 304 0
"GET /admin/jsi18n/ HTTP/1.1" 200 3342
"GET /static/admin/js/filters.js HTTP/1.1" 200 978
"GET /static/admin/js/nav_sidebar.js HTTP/1.1" 304 0
"GET /static/admin/img/icon-viewlink.svg HTTP/1.1" 200 581
"GET /static/admin/img/icon-addlink.svg HTTP/1.1" 200 331
"GET /static/admin/img/tooltag-add.svg HTTP/1.1" 200 331
Not Found: /favicon.ico
Watching for file changes with StatReloader
/app/taskmanager/settings.py changed, reloading.
Watching for file changes with StatReloader
Not Found: /
"GET / HTTP/1.1" 404 2648
Not Found: /favicon.ico
Internal Server Error: /admin/
Traceback (most recent call last):
  File "/usr/local/lib/python3.13/site-packages/django/contrib/sessions/backends/base.py", line 244, in _get_session
    return self._session_cache
           ^^^^^^^^^^^^^^^^^^^
AttributeError: 'SessionStore' object has no attribute '_session_cache'

During handling of the above exception, another exception occurred:

Traceback (most recent call last):
  File "/usr/local/lib/python3.13/site-packages/django/db/backends/utils.py", line 105, in _execute
    return self.cursor.execute(sql, params)
           ~~~~~~~~~~~~~~~~~~~^^^^^^^^^^^^^
psycopg2.errors.UndefinedTable: relation "django_session" does not exist
LINE 1: ...ession_data", "django_session"."expire_date" FROM "django_se...
                                                             ^


The above exception was the direct cause of the following exception:

Traceback (most recent call last):
  File "/usr/local/lib/python3.13/site-packages/django/core/handlers/exception.py", line 55, in inner
    response = get_response(request)
  File "/usr/local/lib/python3.13/site-packages/django/core/handlers/base.py", line 197, in _get_response
    response = wrapped_callback(request, *callback_args, **callback_kwargs)
  File "/usr/local/lib/python3.13/site-packages/django/contrib/admin/sites.py", line 260, in wrapper
    return self.admin_view(view, cacheable)(*args, **kwargs)
           ~~~~~~~~~~~~~~~~~~~~~~~~~~~~~~~~^^^^^^^^^^^^^^^^^
  File "/usr/local/lib/python3.13/site-packages/django/utils/decorators.py", line 188, in _view_wrapper
    result = _process_exception(request, e)
  File "/usr/local/lib/python3.13/site-packages/django/utils/decorators.py", line 186, in _view_wrapper
    response = view_func(request, *args, **kwargs)
  File "/usr/local/lib/python3.13/site-packages/django/views/decorators/cache.py", line 80, in _view_wrapper
    response = view_func(request, *args, **kwargs)
  File "/usr/local/lib/python3.13/site-packages/django/contrib/admin/sites.py", line 229, in inner
    if not self.has_permission(request):
           ~~~~~~~~~~~~~~~~~~~^^^^^^^^^
  File "/usr/local/lib/python3.13/site-packages/django/contrib/admin/sites.py", line 202, in has_permission
    return request.user.is_active and request.user.is_staff
           ^^^^^^^^^^^^^^^^^^^^^^
  File "/usr/local/lib/python3.13/site-packages/django/utils/functional.py", line 251, in inner
    self._setup()
    ~~~~~~~~~~~^^
  File "/usr/local/lib/python3.13/site-packages/django/utils/functional.py", line 404, in _setup
    self._wrapped = self._setupfunc()
                    ~~~~~~~~~~~~~~~^^
  File "/usr/local/lib/python3.13/site-packages/django/contrib/auth/middleware.py", line 37, in <lambda>
    request.user = SimpleLazyObject(lambda: get_user(request))
                                            ~~~~~~~~^^^^^^^^^
  File "/usr/local/lib/python3.13/site-packages/django/contrib/auth/middleware.py", line 17, in get_user
    request._cached_user = auth.get_user(request)
                           ~~~~~~~~~~~~~^^^^^^^^^
  File "/usr/local/lib/python3.13/site-packages/django/contrib/auth/__init__.py", line 209, in get_user
    user_id = _get_user_session_key(request)
  File "/usr/local/lib/python3.13/site-packages/django/contrib/auth/__init__.py", line 62, in _get_user_session_key
    return get_user_model()._meta.pk.to_python(request.session[SESSION_KEY])
                                               ~~~~~~~~~~~~~~~^^^^^^^^^^^^^
  File "/usr/local/lib/python3.13/site-packages/django/contrib/sessions/backends/base.py", line 55, in __getitem__
    return self._session[key]
           ^^^^^^^^^^^^^
  File "/usr/local/lib/python3.13/site-packages/django/contrib/sessions/backends/base.py", line 249, in _get_session
    self._session_cache = self.load()
                          ~~~~~~~~~^^
  File "/usr/local/lib/python3.13/site-packages/django/contrib/sessions/backends/db.py", line 55, in load
    s = self._get_session_from_db()
  File "/usr/local/lib/python3.13/site-packages/django/contrib/sessions/backends/db.py", line 34, in _get_session_from_db
    return self.model.objects.get(
           ~~~~~~~~~~~~~~~~~~~~~~^
        session_key=self.session_key, expire_date__gt=timezone.now()
        ^^^^^^^^^^^^^^^^^^^^^^^^^^^^^^^^^^^^^^^^^^^^^^^^^^^^^^^^^^^^
    )
    ^
  File "/usr/local/lib/python3.13/site-packages/django/db/models/manager.py", line 87, in manager_method
    return getattr(self.get_queryset(), name)(*args, **kwargs)
           ~~~~~~~~~~~~~~~~~~~~~~~~~~~~~~~~~~^^^^^^^^^^^^^^^^^
  File "/usr/local/lib/python3.13/site-packages/django/db/models/query.py", line 645, in get
    num = len(clone)
  File "/usr/local/lib/python3.13/site-packages/django/db/models/query.py", line 382, in __len__
    self._fetch_all()
    ~~~~~~~~~~~~~~~^^
  File "/usr/local/lib/python3.13/site-packages/django/db/models/query.py", line 1928, in _fetch_all
    self._result_cache = list(self._iterable_class(self))
                         ~~~~^^^^^^^^^^^^^^^^^^^^^^^^^^^^
  File "/usr/local/lib/python3.13/site-packages/django/db/models/query.py", line 91, in __iter__
    results = compiler.execute_sql(
        chunked_fetch=self.chunked_fetch, chunk_size=self.chunk_size
    )
  File "/usr/local/lib/python3.13/site-packages/django/db/models/sql/compiler.py", line 1574, in execute_sql
    cursor.execute(sql, params)
    ~~~~~~~~~~~~~~^^^^^^^^^^^^^
  File "/usr/local/lib/python3.13/site-packages/django/db/backends/utils.py", line 122, in execute
    return super().execute(sql, params)
           ~~~~~~~~~~~~~~~^^^^^^^^^^^^^
  File "/usr/local/lib/python3.13/site-packages/django/db/backends/utils.py", line 79, in execute
    return self._execute_with_wrappers(
           ~~~~~~~~~~~~~~~~~~~~~~~~~~~^
        sql, params, many=False, executor=self._execute
        ^^^^^^^^^^^^^^^^^^^^^^^^^^^^^^^^^^^^^^^^^^^^^^^
    )
    ^
  File "/usr/local/lib/python3.13/site-packages/django/db/backends/utils.py", line 92, in _execute_with_wrappers
    return executor(sql, params, many, context)
  File "/usr/local/lib/python3.13/site-packages/django/db/backends/utils.py", line 100, in _execute
    with self.db.wrap_database_errors:
         ^^^^^^^^^^^^^^^^^^^^^^^^^^^^
  File "/usr/local/lib/python3.13/site-packages/django/db/utils.py", line 91, in __exit__
    raise dj_exc_value.with_traceback(traceback) from exc_value
  File "/usr/local/lib/python3.13/site-packages/django/db/backends/utils.py", line 105, in _execute
    return self.cursor.execute(sql, params)
           ~~~~~~~~~~~~~~~~~~~^^^^^^^^^^^^^
django.db.utils.ProgrammingError: relation "django_session" does not exist
LINE 1: ...ession_data", "django_session"."expire_date" FROM "django_se...
                                                             ^

"GET /admin/ HTTP/1.1" 500 193751
/app/taskmanager/settings.py changed, reloading.
Watching for file changes with StatReloader
Not Found: /
"GET / HTTP/1.1" 404 2648
Internal Server Error: /admin/
Traceback (most recent call last):
  File "/usr/local/lib/python3.13/site-packages/django/contrib/sessions/backends/base.py", line 244, in _get_session
    return self._session_cache
           ^^^^^^^^^^^^^^^^^^^
AttributeError: 'SessionStore' object has no attribute '_session_cache'

During handling of the above exception, another exception occurred:

Traceback (most recent call last):
  File "/usr/local/lib/python3.13/site-packages/django/db/backends/utils.py", line 105, in _execute
    return self.cursor.execute(sql, params)
           ~~~~~~~~~~~~~~~~~~~^^^^^^^^^^^^^
psycopg2.errors.UndefinedTable: relation "django_session" does not exist
LINE 1: ...ession_data", "django_session"."expire_date" FROM "django_se...
                                                             ^


The above exception was the direct cause of the following exception:

Traceback (most recent call last):
  File "/usr/local/lib/python3.13/site-packages/django/core/handlers/exception.py", line 55, in inner
    response = get_response(request)
  File "/usr/local/lib/python3.13/site-packages/django/core/handlers/base.py", line 197, in _get_response
    response = wrapped_callback(request, *callback_args, **callback_kwargs)
  File "/usr/local/lib/python3.13/site-packages/django/contrib/admin/sites.py", line 260, in wrapper
    return self.admin_view(view, cacheable)(*args, **kwargs)
           ~~~~~~~~~~~~~~~~~~~~~~~~~~~~~~~~^^^^^^^^^^^^^^^^^
  File "/usr/local/lib/python3.13/site-packages/django/utils/decorators.py", line 188, in _view_wrapper
    result = _process_exception(request, e)
  File "/usr/local/lib/python3.13/site-packages/django/utils/decorators.py", line 186, in _view_wrapper
    response = view_func(request, *args, **kwargs)
  File "/usr/local/lib/python3.13/site-packages/django/views/decorators/cache.py", line 80, in _view_wrapper
    response = view_func(request, *args, **kwargs)
  File "/usr/local/lib/python3.13/site-packages/django/contrib/admin/sites.py", line 229, in inner
    if not self.has_permission(request):
           ~~~~~~~~~~~~~~~~~~~^^^^^^^^^
  File "/usr/local/lib/python3.13/site-packages/django/contrib/admin/sites.py", line 202, in has_permission
    return request.user.is_active and request.user.is_staff
           ^^^^^^^^^^^^^^^^^^^^^^
  File "/usr/local/lib/python3.13/site-packages/django/utils/functional.py", line 251, in inner
    self._setup()
    ~~~~~~~~~~~^^
  File "/usr/local/lib/python3.13/site-packages/django/utils/functional.py", line 404, in _setup
    self._wrapped = self._setupfunc()
                    ~~~~~~~~~~~~~~~^^
  File "/usr/local/lib/python3.13/site-packages/django/contrib/auth/middleware.py", line 37, in <lambda>
    request.user = SimpleLazyObject(lambda: get_user(request))
                                            ~~~~~~~~^^^^^^^^^
  File "/usr/local/lib/python3.13/site-packages/django/contrib/auth/middleware.py", line 17, in get_user
    request._cached_user = auth.get_user(request)
                           ~~~~~~~~~~~~~^^^^^^^^^
  File "/usr/local/lib/python3.13/site-packages/django/contrib/auth/__init__.py", line 209, in get_user
    user_id = _get_user_session_key(request)
  File "/usr/local/lib/python3.13/site-packages/django/contrib/auth/__init__.py", line 62, in _get_user_session_key
    return get_user_model()._meta.pk.to_python(request.session[SESSION_KEY])
                                               ~~~~~~~~~~~~~~~^^^^^^^^^^^^^
  File "/usr/local/lib/python3.13/site-packages/django/contrib/sessions/backends/base.py", line 55, in __getitem__
    return self._session[key]
           ^^^^^^^^^^^^^
  File "/usr/local/lib/python3.13/site-packages/django/contrib/sessions/backends/base.py", line 249, in _get_session
    self._session_cache = self.load()
                          ~~~~~~~~~^^
  File "/usr/local/lib/python3.13/site-packages/django/contrib/sessions/backends/db.py", line 55, in load
    s = self._get_session_from_db()
  File "/usr/local/lib/python3.13/site-packages/django/contrib/sessions/backends/db.py", line 34, in _get_session_from_db
    return self.model.objects.get(
           ~~~~~~~~~~~~~~~~~~~~~~^
        session_key=self.session_key, expire_date__gt=timezone.now()
        ^^^^^^^^^^^^^^^^^^^^^^^^^^^^^^^^^^^^^^^^^^^^^^^^^^^^^^^^^^^^
    )
    ^
  File "/usr/local/lib/python3.13/site-packages/django/db/models/manager.py", line 87, in manager_method
    return getattr(self.get_queryset(), name)(*args, **kwargs)
           ~~~~~~~~~~~~~~~~~~~~~~~~~~~~~~~~~~^^^^^^^^^^^^^^^^^
  File "/usr/local/lib/python3.13/site-packages/django/db/models/query.py", line 645, in get
    num = len(clone)
  File "/usr/local/lib/python3.13/site-packages/django/db/models/query.py", line 382, in __len__
    self._fetch_all()
    ~~~~~~~~~~~~~~~^^
  File "/usr/local/lib/python3.13/site-packages/django/db/models/query.py", line 1928, in _fetch_all
    self._result_cache = list(self._iterable_class(self))
                         ~~~~^^^^^^^^^^^^^^^^^^^^^^^^^^^^
  File "/usr/local/lib/python3.13/site-packages/django/db/models/query.py", line 91, in __iter__
    results = compiler.execute_sql(
        chunked_fetch=self.chunked_fetch, chunk_size=self.chunk_size
    )
  File "/usr/local/lib/python3.13/site-packages/django/db/models/sql/compiler.py", line 1574, in execute_sql
    cursor.execute(sql, params)
    ~~~~~~~~~~~~~~^^^^^^^^^^^^^
  File "/usr/local/lib/python3.13/site-packages/django/db/backends/utils.py", line 122, in execute
    return super().execute(sql, params)
           ~~~~~~~~~~~~~~~^^^^^^^^^^^^^
  File "/usr/local/lib/python3.13/site-packages/django/db/backends/utils.py", line 79, in execute
    return self._execute_with_wrappers(
           ~~~~~~~~~~~~~~~~~~~~~~~~~~~^
        sql, params, many=False, executor=self._execute
        ^^^^^^^^^^^^^^^^^^^^^^^^^^^^^^^^^^^^^^^^^^^^^^^
    )
    ^
  File "/usr/local/lib/python3.13/site-packages/django/db/backends/utils.py", line 92, in _execute_with_wrappers
    return executor(sql, params, many, context)
  File "/usr/local/lib/python3.13/site-packages/django/db/backends/utils.py", line 100, in _execute
    with self.db.wrap_database_errors:
         ^^^^^^^^^^^^^^^^^^^^^^^^^^^^
  File "/usr/local/lib/python3.13/site-packages/django/db/utils.py", line 91, in __exit__
    raise dj_exc_value.with_traceback(traceback) from exc_value
  File "/usr/local/lib/python3.13/site-packages/django/db/backends/utils.py", line 105, in _execute
    return self.cursor.execute(sql, params)
           ~~~~~~~~~~~~~~~~~~~^^^^^^^^^^^^^
django.db.utils.ProgrammingError: relation "django_session" does not exist
LINE 1: ...ession_data", "django_session"."expire_date" FROM "django_se...
                                                             ^

"GET /admin/ HTTP/1.1" 500 193912
Not Found: /favicon.ico
"GET /favicon.ico HTTP/1.1" 404 2699
/app/taskmanager/settings.py changed, reloading.
Watching for file changes with StatReloader
Not Found: /
"GET / HTTP/1.1" 404 179
"GET /admin/ HTTP/1.1" 302 0
"GET /admin/login/?next=/admin/ HTTP/1.1" 200 4160
Not Found: /static/admin/css/base.css
Not Found: /static/admin/css/dark_mode.css
"GET /static/admin/css/base.css HTTP/1.1" 404 179
Not Found: /static/admin/css/nav_sidebar.css
Not Found: /static/admin/css/login.css
"GET /static/admin/css/dark_mode.css HTTP/1.1" 404 179
"GET /static/admin/css/nav_sidebar.css HTTP/1.1" 404 179
Not Found: /static/admin/js/theme.js
Not Found: /static/admin/css/responsive.css
"GET /static/admin/css/login.css HTTP/1.1" 404 179
"GET /static/admin/js/theme.js HTTP/1.1" 404 179
"GET /static/admin/css/responsive.css HTTP/1.1" 404 179
Not Found: /static/admin/css/nav_sidebar.css
Not Found: /static/admin/css/login.css
"GET /static/admin/css/nav_sidebar.css HTTP/1.1" 404 179
"GET /static/admin/css/login.css HTTP/1.1" 404 179
Not Found: /static/admin/js/nav_sidebar.js
"GET /static/admin/js/nav_sidebar.js HTTP/1.1" 404 179
Not Found: /favicon.ico
"GET /favicon.ico HTTP/1.1" 404 179
"GET /admin/login/?next=/admin/ HTTP/1.1" 200 4160
Not Found: /static/admin/css/base.css
Not Found: /static/admin/js/theme.js
Not Found: /static/admin/js/nav_sidebar.js
"GET /static/admin/css/base.css HTTP/1.1" 404 179
Not Found: /static/admin/css/login.css
Not Found: /static/admin/css/dark_mode.css
Not Found: /static/admin/css/nav_sidebar.css
"GET /static/admin/js/theme.js HTTP/1.1" 404 179
Not Found: /static/admin/css/responsive.css
"GET /static/admin/js/nav_sidebar.js HTTP/1.1" 404 179
"GET /static/admin/css/login.css HTTP/1.1" 404 179
"GET /static/admin/css/dark_mode.css HTTP/1.1" 404 179
"GET /static/admin/css/nav_sidebar.css HTTP/1.1" 404 179
"GET /static/admin/css/responsive.css HTTP/1.1" 404 179
Not Found: /favicon.ico
"GET /favicon.ico HTTP/1.1" 404 179
"POST /admin/login/?next=/admin/ HTTP/1.1" 302 0
"GET /admin/ HTTP/1.1" 200 6643
Not Found: /static/admin/css/base.css
Not Found: /static/admin/css/dark_mode.css
Not Found: /static/admin/js/theme.js
Not Found: /static/admin/css/nav_sidebar.css
"GET /static/admin/css/dark_mode.css HTTP/1.1" 404 179
Not Found: /static/admin/js/nav_sidebar.js
Not Found: /static/admin/css/responsive.css
"GET /static/admin/css/base.css HTTP/1.1" 404 179
"GET /static/admin/js/theme.js HTTP/1.1" 404 179
"GET /static/admin/js/nav_sidebar.js HTTP/1.1" 404 179
"GET /static/admin/css/responsive.css HTTP/1.1" 404 179
"GET /static/admin/css/nav_sidebar.css HTTP/1.1" 404 179
Not Found: /static/admin/css/dashboard.css
"GET /static/admin/css/dashboard.css HTTP/1.1" 404 179
Not Found: /favicon.ico
"GET /admin/ HTTP/1.1" 200 6643
Not Found: /static/admin/css/base.css
Not Found: /static/admin/css/dark_mode.css
"GET /static/admin/css/base.css HTTP/1.1" 404 179
Not Found: /static/admin/js/theme.js
"GET /static/admin/css/dark_mode.css HTTP/1.1" 404 179
Not Found: /static/admin/css/nav_sidebar.css
Not Found: /static/admin/css/responsive.css
"GET /static/admin/js/theme.js HTTP/1.1" 404 179
Not Found: /static/admin/js/nav_sidebar.js
"GET /static/admin/css/responsive.css HTTP/1.1" 404 179
Not Found: /static/admin/css/dashboard.css
"GET /static/admin/css/nav_sidebar.css HTTP/1.1" 404 179
"GET /static/admin/js/nav_sidebar.js HTTP/1.1" 404 179
"GET /static/admin/css/dashboard.css HTTP/1.1" 404 179
"GET /admin/ HTTP/1.1" 200 6643
Not Found: /static/admin/css/base.css
Not Found: /static/admin/js/theme.js
Not Found: /static/admin/js/nav_sidebar.js
Not Found: /static/admin/css/dark_mode.css
Not Found: /static/admin/css/nav_sidebar.css
Not Found: /static/admin/css/dashboard.css
"GET /static/admin/js/nav_sidebar.js HTTP/1.1" 404 179
"GET /static/admin/js/theme.js HTTP/1.1" 404 179
"GET /static/admin/css/dashboard.css HTTP/1.1" 404 179
Not Found: /static/admin/css/responsive.css
"GET /static/admin/css/base.css HTTP/1.1" 404 179
"GET /static/admin/css/dark_mode.css HTTP/1.1" 404 179
"GET /static/admin/css/nav_sidebar.css HTTP/1.1" 404 179
Not Found: /static/admin/js/nav_sidebar.js
"GET /static/admin/css/responsive.css HTTP/1.1" 404 179
"GET /static/admin/js/nav_sidebar.js HTTP/1.1" 404 179
Not Found: /
"GET / HTTP/1.1" 404 179
Not Found: /adin
"GET /adin HTTP/1.1" 404 179
"GET /admin/ HTTP/1.1" 200 6643
Not Found: /static/admin/css/base.css
Not Found: /static/admin/css/nav_sidebar.css
Not Found: /static/admin/css/dark_mode.css
Not Found: /static/admin/js/nav_sidebar.js
Not Found: /static/admin/css/dashboard.css
Not Found: /static/admin/js/theme.js
"GET /static/admin/css/nav_sidebar.css HTTP/1.1" 404 179
"GET /static/admin/css/dashboard.css HTTP/1.1" 404 179
"GET /static/admin/css/dark_mode.css HTTP/1.1" 404 179
"GET /static/admin/css/base.css HTTP/1.1" 404 179
Not Found: /static/admin/css/responsive.css
"GET /static/admin/css/responsive.css HTTP/1.1" 404 179
"GET /static/admin/js/nav_sidebar.js HTTP/1.1" 404 179
"GET /static/admin/js/theme.js HTTP/1.1" 404 179
Not Found: /static/admin/css/nav_sidebar.css
Not Found: /static/admin/css/dashboard.css
Not Found: /static/admin/js/nav_sidebar.js
"GET /static/admin/css/nav_sidebar.css HTTP/1.1" 404 179
"GET /static/admin/css/dashboard.css HTTP/1.1" 404 179
"GET /static/admin/js/nav_sidebar.js HTTP/1.1" 404 179
Watching for file changes with StatReloader
"GET /admin/ HTTP/1.1" 200 6643
"GET /static/admin/css/nav_sidebar.css HTTP/1.1" 200 2810
"GET /static/admin/js/theme.js HTTP/1.1" 200 1653
"GET /static/admin/css/dark_mode.css HTTP/1.1" 200 2804
"GET /static/admin/css/dashboard.css HTTP/1.1" 200 441
"GET /static/admin/js/nav_sidebar.js HTTP/1.1" 200 3063
"GET /static/admin/css/base.css HTTP/1.1" 200 22092
"GET /static/admin/css/responsive.css HTTP/1.1" 200 17972
"GET /static/admin/img/icon-changelink.svg HTTP/1.1" 200 380
"GET /static/admin/img/icon-addlink.svg HTTP/1.1" 200 331
Internal Server Error: /admin/tasks/task/
Traceback (most recent call last):
  File "/usr/local/lib/python3.13/site-packages/django/db/backends/utils.py", line 105, in _execute
    return self.cursor.execute(sql, params)
           ~~~~~~~~~~~~~~~~~~~^^^^^^^^^^^^^
psycopg2.errors.UndefinedTable: relation "tasks_task" does not exist
LINE 1: SELECT COUNT(*) AS "__count" FROM "tasks_task"
                                          ^


The above exception was the direct cause of the following exception:

Traceback (most recent call last):
  File "/usr/local/lib/python3.13/site-packages/django/core/handlers/exception.py", line 55, in inner
    response = get_response(request)
  File "/usr/local/lib/python3.13/site-packages/django/core/handlers/base.py", line 197, in _get_response
    response = wrapped_callback(request, *callback_args, **callback_kwargs)
  File "/usr/local/lib/python3.13/site-packages/django/contrib/admin/options.py", line 718, in wrapper
    return self.admin_site.admin_view(view)(*args, **kwargs)
           ~~~~~~~~~~~~~~~~~~~~~~~~~~~~~~~~^^^^^^^^^^^^^^^^^
  File "/usr/local/lib/python3.13/site-packages/django/utils/decorators.py", line 188, in _view_wrapper
    result = _process_exception(request, e)
  File "/usr/local/lib/python3.13/site-packages/django/utils/decorators.py", line 186, in _view_wrapper
    response = view_func(request, *args, **kwargs)
  File "/usr/local/lib/python3.13/site-packages/django/views/decorators/cache.py", line 80, in _view_wrapper
    response = view_func(request, *args, **kwargs)
  File "/usr/local/lib/python3.13/site-packages/django/contrib/admin/sites.py", line 241, in inner
    return view(request, *args, **kwargs)
  File "/usr/local/lib/python3.13/site-packages/django/utils/decorators.py", line 48, in _wrapper
    return bound_method(*args, **kwargs)
  File "/usr/local/lib/python3.13/site-packages/django/utils/decorators.py", line 188, in _view_wrapper
    result = _process_exception(request, e)
  File "/usr/local/lib/python3.13/site-packages/django/utils/decorators.py", line 186, in _view_wrapper
    response = view_func(request, *args, **kwargs)
  File "/usr/local/lib/python3.13/site-packages/django/contrib/admin/options.py", line 1999, in changelist_view
    cl = self.get_changelist_instance(request)
  File "/usr/local/lib/python3.13/site-packages/django/contrib/admin/options.py", line 866, in get_changelist_instance
    return ChangeList(
        request,
    ...<12 lines>...
        self.search_help_text,
    )
  File "/usr/local/lib/python3.13/site-packages/django/contrib/admin/views/main.py", line 146, in __init__
    self.get_results(request)
    ~~~~~~~~~~~~~~~~^^^^^^^^^
  File "/usr/local/lib/python3.13/site-packages/django/contrib/admin/views/main.py", line 313, in get_results
    result_count = paginator.count
                   ^^^^^^^^^^^^^^^
  File "/usr/local/lib/python3.13/site-packages/django/utils/functional.py", line 47, in __get__
    res = instance.__dict__[self.name] = self.func(instance)
                                         ~~~~~~~~~^^^^^^^^^^
  File "/usr/local/lib/python3.13/site-packages/django/core/paginator.py", line 110, in count
    return c()
  File "/usr/local/lib/python3.13/site-packages/django/db/models/query.py", line 620, in count
    return self.query.get_count(using=self.db)
           ~~~~~~~~~~~~~~~~~~~~^^^^^^^^^^^^^^^
  File "/usr/local/lib/python3.13/site-packages/django/db/models/sql/query.py", line 630, in get_count
    return obj.get_aggregation(using, {"__count": Count("*")})["__count"]
           ~~~~~~~~~~~~~~~~~~~^^^^^^^^^^^^^^^^^^^^^^^^^^^^^^^^
  File "/usr/local/lib/python3.13/site-packages/django/db/models/sql/query.py", line 616, in get_aggregation
    result = compiler.execute_sql(SINGLE)
  File "/usr/local/lib/python3.13/site-packages/django/db/models/sql/compiler.py", line 1574, in execute_sql
    cursor.execute(sql, params)
    ~~~~~~~~~~~~~~^^^^^^^^^^^^^
  File "/usr/local/lib/python3.13/site-packages/django/db/backends/utils.py", line 79, in execute
    return self._execute_with_wrappers(
           ~~~~~~~~~~~~~~~~~~~~~~~~~~~^
        sql, params, many=False, executor=self._execute
        ^^^^^^^^^^^^^^^^^^^^^^^^^^^^^^^^^^^^^^^^^^^^^^^
    )
    ^
  File "/usr/local/lib/python3.13/site-packages/django/db/backends/utils.py", line 92, in _execute_with_wrappers
    return executor(sql, params, many, context)
  File "/usr/local/lib/python3.13/site-packages/django/db/backends/utils.py", line 100, in _execute
    with self.db.wrap_database_errors:
         ^^^^^^^^^^^^^^^^^^^^^^^^^^^^
  File "/usr/local/lib/python3.13/site-packages/django/db/utils.py", line 91, in __exit__
    raise dj_exc_value.with_traceback(traceback) from exc_value
  File "/usr/local/lib/python3.13/site-packages/django/db/backends/utils.py", line 105, in _execute
    return self.cursor.execute(sql, params)
           ~~~~~~~~~~~~~~~~~~~^^^^^^^^^^^^^
django.db.utils.ProgrammingError: relation "tasks_task" does not exist
LINE 1: SELECT COUNT(*) AS "__count" FROM "tasks_task"
                                          ^

"GET /admin/tasks/task/ HTTP/1.1" 500 145
"GET /admin/ HTTP/1.1" 200 6643
"GET /admin/tasks/task/ HTTP/1.1" 200 9551
"GET /static/admin/css/dark_mode.css HTTP/1.1" 304 0
"GET /static/admin/js/theme.js HTTP/1.1" 304 0
"GET /static/admin/css/base.css HTTP/1.1" 304 0
"GET /static/admin/css/nav_sidebar.css HTTP/1.1" 304 0
"GET /static/admin/js/nav_sidebar.js HTTP/1.1" 304 0
"GET /static/admin/css/responsive.css HTTP/1.1" 304 0
"GET /static/admin/js/vendor/jquery/jquery.min.js HTTP/1.1" 200 87533
"GET /static/admin/js/vendor/xregexp/xregexp.min.js HTTP/1.1" 200 163184
"GET /static/admin/js/filters.js HTTP/1.1" 200 978
"GET /static/admin/js/jquery.init.js HTTP/1.1" 200 347
"GET /static/admin/css/changelists.css HTTP/1.1" 200 6878
"GET /static/admin/js/actions.js HTTP/1.1" 200 8076
"GET /static/admin/js/prepopulate.js HTTP/1.1" 200 1531
"GET /admin/jsi18n/ HTTP/1.1" 200 3342
"GET /static/admin/js/urlify.js HTTP/1.1" 200 7887
"GET /static/admin/js/admin/RelatedObjectLookups.js HTTP/1.1" 200 9097
"GET /static/admin/js/core.js HTTP/1.1" 200 6208
"GET /static/admin/img/search.svg HTTP/1.1" 200 458
"GET /static/admin/img/icon-addlink.svg HTTP/1.1" 200 331
"GET /static/admin/img/tooltag-add.svg HTTP/1.1" 200 331
"GET /static/admin/img/icon-viewlink.svg HTTP/1.1" 200 581
"GET /admin/tasks/task/add/ HTTP/1.1" 200 12527
"GET /static/admin/css/forms.css HTTP/1.1" 200 8794
"GET /admin/jsi18n/ HTTP/1.1" 200 3342
"GET /static/admin/css/widgets.css HTTP/1.1" 200 11564
"GET /static/admin/js/prepopulate_init.js HTTP/1.1" 200 586
"GET /static/admin/js/change_form.js HTTP/1.1" 200 606
"GET /static/admin/img/icon-changelink.svg HTTP/1.1" 200 380
"POST /admin/tasks/task/add/ HTTP/1.1" 302 0
"GET /admin/tasks/task/ HTTP/1.1" 200 11626
"GET /admin/jsi18n/ HTTP/1.1" 200 3342
"GET /static/admin/img/icon-no.svg HTTP/1.1" 200 560
"GET /static/admin/img/icon-yes.svg HTTP/1.1" 200 436
Not Found: /favicon.ico
"GET /favicon.ico HTTP/1.1" 404 179
"GET /admin/tasks/task/1/change/ HTTP/1.1" 200 12813
"GET /admin/jsi18n/ HTTP/1.1" 200 3342
"POST /admin/tasks/task/1/change/ HTTP/1.1" 302 0
"GET /admin/tasks/task/ HTTP/1.1" 200 11628
"GET /admin/jsi18n/ HTTP/1.1" 200 3342
Not Found: /favicon.ico
"GET /favicon.ico HTTP/1.1" 404 179
